Workbook

Sheet Monte Carlo
A1: MONTE CARLO COST MODEL
A2: 5,000 iterations run live in-sheet. Edit the yellow input cells, then press F9 to re-roll. Stats below update automatically. | M2: ↓ SIMULATION ENGINE — one row per iteration (safe to ignore / collapse)
A4: Item | B4: Distribution | C4: P1 | D4: P2 | E4: P3 | F4: Central | H4: SETTINGS | M4: Labor | N4: Materials | O4: Equipment | P4: Subcontractors | Q4: Permits & Fees | R4: Risk Reserve | S4: Total
A5: Labor | B5: pert | C5: 40000 | D5: 55000 | E5: 90000 | F5: =(C5+4*D5+E5)/6 | H5: Iterations | I5: 5000 | M5: =_xlfn.BETA.INV($AA5,1+4*($D$5-$C$5)/($E$5-$C$5),1+4*($E$5-$D$5)/($E$5-$C$5),$C$5,$E$5) | N5: =IF($AB5<($D$6-$C$6)/($E$6-$C$6),$C$6+SQRT($AB5*($E$6-$C$6)*($D$6-$C$6)),$E$6-SQRT((1-$AB5)*($E$6-$C$6)*($E$6-$D$6))) | O5: =_xlfn.NORM.INV($AC5,$C$7,$D$7) | P5: =$C$8+($D$8-$C$8)*$AD5 | Q5: =$C$9 | R5: =_xlfn.LOGNORM.INV($AF5,LN($C$10)-0.5*LN(1+($D$10/$C$10)^2),SQRT(LN(1+($D$10/$C$10)^2))) | S5: =SUM(M5:R5) | AA5: =RAND() | AB5: =RAND() | AC5: =RAND() | AD5: =RAND() | AE5: =RAND() | AF5: =RAND()
A6: Materials | B6: triangular | C6: 30000 | D6: 38000 | E6: 60000 | F6: =(C6+D6+E6)/3 | H6: Budget | I6: 185000 | M6: =_xlfn.BETA.INV($AA6,1+4*($D$5-$C$5)/($E$5-$C$5),1+4*($E$5-$D$5)/($E$5-$C$5),$C$5,$E$5) | N6: =IF($AB6<($D$6-$C$6)/($E$6-$C$6),$C$6+SQRT($AB6*($E$6-$C$6)*($D$6-$C$6)),$E$6-SQRT((1-$AB6)*($E$6-$C$6)*($E$6-$D$6))) | O6: =_xlfn.NORM.INV($AC6,$C$7,$D$7) | P6: =$C$8+($D$8-$C$8)*$AD6 | Q6: =$C$9 | R6: =_xlfn.LOGNORM.INV($AF6,LN($C$10)-0.5*LN(1+($D$10/$C$10)^2),SQRT(LN(1+($D$10/$C$10)^2))) | S6: =SUM(M6:R6) | AA6: =RAND() | AB6: =RAND() | AC6: =RAND() | AD6: =RAND() | AE6: =RAND() | AF6: =RAND()
A7: Equipment | B7: normal | C7: 15000 | D7: 3000 | F7: =C7 | H7: Confidence | I7: 0.8 | M7: =_xlfn.BETA.INV($AA7,1+4*($D$5-$C$5)/($E$5-$C$5),1+4*($E$5-$D$5)/($E$5-$C$5),$C$5,$E$5) | N7: =IF($AB7<($D$6-$C$6)/($E$6-$C$6),$C$6+SQRT($AB7*($E$6-$C$6)*($D$6-$C$6)),$E$6-SQRT((1-$AB7)*($E$6-$C$6)*($E$6-$D$6))) | O7: =_xlfn.NORM.INV($AC7,$C$7,$D$7) | P7: =$C$8+($D$8-$C$8)*$AD7 | Q7: =$C$9 | R7: =_xlfn.LOGNORM.INV($AF7,LN($C$10)-0.5*LN(1+($D$10/$C$10)^2),SQRT(LN(1+($D$10/$C$10)^2))) | S7: =SUM(M7:R7) | AA7: =RAND() | AB7: =RAND() | AC7: =RAND() | AD7: =RAND() | AE7: =RAND() | AF7: =RAND()
A8: Subcontractors | B8: uniform | C8: 20000 | D8: 35000 | F8: =(C8+D8)/2 | M8: =_xlfn.BETA.INV($AA8,1+4*($D$5-$C$5)/($E$5-$C$5),1+4*($E$5-$D$5)/($E$5-$C$5),$C$5,$E$5) | N8: =IF($AB8<($D$6-$C$6)/($E$6-$C$6),$C$6+SQRT($AB8*($E$6-$C$6)*($D$6-$C$6)),$E$6-SQRT((1-$AB8)*($E$6-$C$6)*($E$6-$D$6))) | O8: =_xlfn.NORM.INV($AC8,$C$7,$D$7) | P8: =$C$8+($D$8-$C$8)*$AD8 | Q8: =$C$9 | R8: =_xlfn.LOGNORM.INV($AF8,LN($C$10)-0.5*LN(1+($D$10/$C$10)^2),SQRT(LN(1+($D$10/$C$10)^2))) | S8: =SUM(M8:R8) | AA8: =RAND() | AB8: =RAND() | AC8: =RAND() | AD8: =RAND() | AE8: =RAND() | AF8: =RAND()
A9: Permits & Fees | B9: fixed | C9: 5000 | F9: =C9 | M9: =_xlfn.BETA.INV($AA9,1+4*($D$5-$C$5)/($E$5-$C$5),1+4*($E$5-$D$5)/($E$5-$C$5),$C$5,$E$5) | N9: =IF($AB9<($D$6-$C$6)/($E$6-$C$6),$C$6+SQRT($AB9*($E$6-$C$6)*($D$6-$C$6)),$E$6-SQRT((1-$AB9)*($E$6-$C$6)*($E$6-$D$6))) | O9: =_xlfn.NORM.INV($AC9,$C$7,$D$7) | P9: =$C$8+($D$8-$C$8)*$AD9 | Q9: =$C$9 | R9: =_xlfn.LOGNORM.INV($AF9,LN($C$10)-0.5*LN(1+($D$10/$C$10)^2),SQRT(LN(1+($D$10/$C$10)^2))) | S9: =SUM(M9:R9) | AA9: =RAND() | AB9: =RAND() | AC9: =RAND() | AD9: =RAND() | AE9: =RAND() | AF9: =RAND()
A10: Risk Reserve | B10: lognormal | C10: 8000 | D10: 4000 | F10: =C10 | M10: =_xlfn.BETA.INV($AA10,1+4*($D$5-$C$5)/($E$5-$C$5),1+4*($E$5-$D$5)/($E$5-$C$5),$C$5,$E$5) | N10: =IF($AB10<($D$6-$C$6)/($E$6-$C$6),$C$6+SQRT($AB10*($E$6-$C$6)*($D$6-$C$6)),$E$6-SQRT((1-$AB10)*($E$6-$C$6)*($E$6-$D$6))) | O10: =_xlfn.NORM.INV($AC10,$C$7,$D$7) | P10: =$C$8+($D$8-$C$8)*$AD10 | Q10: =$C$9 | R10: =_xlfn.LOGNORM.INV($AF10,LN($C$10)-0.5*LN(1+($D$10/$C$10)^2),SQRT(LN(1+($D$10/$C$10)^2))) | S10: =SUM(M10:R10) | AA10: =RAND() | AB10: =RAND() | AC10: =RAND() | AD10: =RAND() | AE10: =RAND() | AF10: =RAND()
A11: Base estimate | F11: =SUM(F5:F10) | M11: =_xlfn.BETA.INV($AA11,1+4*($D$5-$C$5)/($E$5-$C$5),1+4*($E$5-$D$5)/($E$5-$C$5),$C$5,$E$5) | N11: =IF($AB11<($D$6-$C$6)/($E$6-$C$6),$C$6+SQRT($AB11*($E$6-$C$6)*($D$6-$C$6)),$E$6-SQRT((1-$AB11)*($E$6-$C$6)*($E$6-$D$6))) | O11: =_xlfn.NORM.INV($AC11,$C$7,$D$7) | P11: =$C$8+($D$8-$C$8)*$AD11 | Q11: =$C$9 | R11: =_xlfn.LOGNORM.INV($AF11,LN($C$10)-0.5*LN(1+($D$10/$C$10)^2),SQRT(LN(1+($D$10/$C$10)^2))) | S11: =SUM(M11:R11) | AA11: =RAND() | AB11: =RAND() | AC11: =RAND() | AD11: =RAND() | AE11: =RAND() | AF11: =RAND()
M12: =_xlfn.BETA.INV($AA12,1+4*($D$5-$C$5)/($E$5-$C$5),1+4*($E$5-$D$5)/($E$5-$C$5),$C$5,$E$5) | N12: =IF($AB12<($D$6-$C$6)/($E$6-$C$6),$C$6+SQRT($AB12*($E$6-$C$6)*($D$6-$C$6)),$E$6-SQRT((1-$AB12)*($E$6-$C$6)*($E$6-$D$6))) | O12: =_xlfn.NORM.INV($AC12,$C$7,$D$7) | P12: =$C$8+($D$8-$C$8)*$AD12 | Q12: =$C$9 | R12: =_xlfn.LOGNORM.INV($AF12,LN($C$10)-0.5*LN(1+($D$10/$C$10)^2),SQRT(LN(1+($D$10/$C$10)^2))) | S12: =SUM(M12:R12) | AA12: =RAND() | AB12: =RAND() | AC12: =RAND() | AD12: =RAND() | AE12: =RAND() | AF12: =RAND()
M13: =_xlfn.BETA.INV($AA13,1+4*($D$5-$C$5)/($E$5-$C$5),1+4*($E$5-$D$5)/($E$5-$C$5),$C$5,$E$5) | N13: =IF($AB13<($D$6-$C$6)/($E$6-$C$6),$C$6+SQRT($AB13*($E$6-$C$6)*($D$6-$C$6)),$E$6-SQRT((1-$AB13)*($E$6-$C$6)*($E$6-$D$6))) | O13: =_xlfn.NORM.INV($AC13,$C$7,$D$7) | P13: =$C$8+($D$8-$C$8)*$AD13 | Q13: =$C$9 | R13: =_xlfn.LOGNORM.INV($AF13,LN($C$10)-0.5*LN(1+($D$10/$C$10)^2),SQRT(LN(1+($D$10/$C$10)^2))) | S13: =SUM(M13:R13) | AA13: =RAND() | AB13: =RAND() | AC13: =RAND() | AD13: =RAND() | AE13: =RAND() | AF13: =RAND()
A14: SUMMARY (live — press F9 to re-roll) | M14: =_xlfn.BETA.INV($AA14,1+4*($D$5-$C$5)/($E$5-$C$5),1+4*($E$5-$D$5)/($E$5-$C$5),$C$5,$E$5) | N14: =IF($AB14<($D$6-$C$6)/($E$6-$C$6),$C$6+SQRT($AB14*($E$6-$C$6)*($D$6-$C$6)),$E$6-SQRT((1-$AB14)*($E$6-$C$6)*($E$6-$D$6))) | O14: =_xlfn.NORM.INV($AC14,$C$7,$D$7) | P14: =$C$8+($D$8-$C$8)*$AD14 | Q14: =$C$9 | R14: =_xlfn.LOGNORM.INV($AF14,LN($C$10)-0.5*LN(1+($D$10/$C$10)^2),SQRT(LN(1+($D$10/$C$10)^2))) | S14: =SUM(M14:R14) | AA14: =RAND() | AB14: =RAND() | AC14: =RAND() | AD14: =RAND() | AE14: =RAND() | AF14: =RAND()
A15: Mean (expected) | B15: =AVERAGE($S$5:$S$5004) | M15: =_xlfn.BETA.INV($AA15,1+4*($D$5-$C$5)/($E$5-$C$5),1+4*($E$5-$D$5)/($E$5-$C$5),$C$5,$E$5) | N15: =IF($AB15<($D$6-$C$6)/($E$6-$C$6),$C$6+SQRT($AB15*($E$6-$C$6)*($D$6-$C$6)),$E$6-SQRT((1-$AB15)*($E$6-$C$6)*($E$6-$D$6))) | O15: =_xlfn.NORM.INV($AC15,$C$7,$D$7) | P15: =$C$8+($D$8-$C$8)*$AD15 | Q15: =$C$9 | R15: =_xlfn.LOGNORM.INV($AF15,LN($C$10)-0.5*LN(1+($D$10/$C$10)^2),SQRT(LN(1+($D$10/$C$10)^2))) | S15: =SUM(M15:R15) | AA15: =RAND() | AB15: =RAND() | AC15: =RAND() | AD15: =RAND() | AE15: =RAND() | AF15: =RAND()
A16: Std deviation | B16: =_xlfn.STDEV.S($S$5:$S$5004) | M16: =_xlfn.BETA.INV($AA16,1+4*($D$5-$C$5)/($E$5-$C$5),1+4*($E$5-$D$5)/($E$5-$C$5),$C$5,$E$5) | N16: =IF($AB16<($D$6-$C$6)/($E$6-$C$6),$C$6+SQRT($AB16*($E$6-$C$6)*($D$6-$C$6)),$E$6-SQRT((1-$AB16)*($E$6-$C$6)*($E$6-$D$6))) | O16: =_xlfn.NORM.INV($AC16,$C$7,$D$7) | P16: =$C$8+($D$8-$C$8)*$AD16 | Q16: =$C$9 | R16: =_xlfn.LOGNORM.INV($AF16,LN($C$10)-0.5*LN(1+($D$10/$C$10)^2),SQRT(LN(1+($D$10/$C$10)^2))) | S16: =SUM(M16:R16) | AA16: =RAND() | AB16: =RAND() | AC16: =RAND() | AD16: =RAND() | AE16: =RAND() | AF16: =RAND()
A17: Minimum | B17: =MIN($S$5:$S$5004) | M17: =_xlfn.BETA.INV($AA17,1+4*($D$5-$C$5)/($E$5-$C$5),1+4*($E$5-$D$5)/($E$5-$C$5),$C$5,$E$5) | N17: =IF($AB17<($D$6-$C$6)/($E$6-$C$6),$C$6+SQRT($AB17*($E$6-$C$6)*($D$6-$C$6)),$E$6-SQRT((1-$AB17)*($E$6-$C$6)*($E$6-$D$6))) | O17: =_xlfn.NORM.INV($AC17,$C$7,$D$7) | P17: =$C$8+($D$8-$C$8)*$AD17 | Q17: =$C$9 | R17: =_xlfn.LOGNORM.INV($AF17,LN($C$10)-0.5*LN(1+($D$10/$C$10)^2),SQRT(LN(1+($D$10/$C$10)^2))) | S17: =SUM(M17:R17) | AA17: =RAND() | AB17: =RAND() | AC17: =RAND() | AD17: =RAND() | AE17: =RAND() | AF17: =RAND()
A18: Maximum | B18: =MAX($S$5:$S$5004) | M18: =_xlfn.BETA.INV($AA18,1+4*($D$5-$C$5)/($E$5-$C$5),1+4*($E$5-$D$5)/($E$5-$C$5),$C$5,$E$5) | N18: =IF($AB18<($D$6-$C$6)/($E$6-$C$6),$C$6+SQRT($AB18*($E$6-$C$6)*($D$6-$C$6)),$E$6-SQRT((1-$AB18)*($E$6-$C$6)*($E$6-$D$6))) | O18: =_xlfn.NORM.INV($AC18,$C$7,$D$7) | P18: =$C$8+($D$8-$C$8)*$AD18 | Q18: =$C$9 | R18: =_xlfn.LOGNORM.INV($AF18,LN($C$10)-0.5*LN(1+($D$10/$C$10)^2),SQRT(LN(1+($D$10/$C$10)^2))) | S18: =SUM(M18:R18) | AA18: =RAND() | AB18: =RAND() | AC18: =RAND() | AD18: =RAND() | AE18: =RAND() | AF18: =RAND()
A19: P10 (optimistic) | B19: =_xlfn.PERCENTILE.INC($S$5:$S$5004,0.1) | M19: =_xlfn.BETA.INV($AA19,1+4*($D$5-$C$5)/($E$5-$C$5),1+4*($E$5-$D$5)/($E$5-$C$5),$C$5,$E$5) | N19: =IF($AB19<($D$6-$C$6)/($E$6-$C$6),$C$6+SQRT($AB19*($E$6-$C$6)*($D$6-$C$6)),$E$6-SQRT((1-$AB19)*($E$6-$C$6)*($E$6-$D$6))) | O19: =_xlfn.NORM.INV($AC19,$C$7,$D$7) | P19: =$C$8+($D$8-$C$8)*$AD19 | Q19: =$C$9 | R19: =_xlfn.LOGNORM.INV($AF19,LN($C$10)-0.5*LN(1+($D$10/$C$10)^2),SQRT(LN(1+($D$10/$C$10)^2))) | S19: =SUM(M19:R19) | AA19: =RAND() | AB19: =RAND() | AC19: =RAND() | AD19: =RAND() | AE19: =RAND() | AF19: =RAND()
A20: P50 (median) | B20: =_xlfn.PERCENTILE.INC($S$5:$S$5004,0.5) | M20: =_xlfn.BETA.INV($AA20,1+4*($D$5-$C$5)/($E$5-$C$5),1+4*($E$5-$D$5)/($E$5-$C$5),$C$5,$E$5) | N20: =IF($AB20<($D$6-$C$6)/($E$6-$C$6),$C$6+SQRT($AB20*($E$6-$C$6)*($D$6-$C$6)),$E$6-SQRT((1-$AB20)*($E$6-$C$6)*($E$6-$D$6))) | O20: =_xlfn.NORM.INV($AC20,$C$7,$D$7) | P20: =$C$8+($D$8-$C$8)*$AD20 | Q20: =$C$9 | R20: =_xlfn.LOGNORM.INV($AF20,LN($C$10)-0.5*LN(1+($D$10/$C$10)^2),SQRT(LN(1+($D$10/$C$10)^2))) | S20: =SUM(M20:R20) | AA20: =RAND() | AB20: =RAND() | AC20: =RAND() | AD20: =RAND() | AE20: =RAND() | AF20: =RAND()
A21: P80 (conservative) | B21: =_xlfn.PERCENTILE.INC($S$5:$S$5004,0.8) | M21: =_xlfn.BETA.INV($AA21,1+4*($D$5-$C$5)/($E$5-$C$5),1+4*($E$5-$D$5)/($E$5-$C$5),$C$5,$E$5) | N21: =IF($AB21<($D$6-$C$6)/($E$6-$C$6),$C$6+SQRT($AB21*($E$6-$C$6)*($D$6-$C$6)),$E$6-SQRT((1-$AB21)*($E$6-$C$6)*($E$6-$D$6))) | O21: =_xlfn.NORM.INV($AC21,$C$7,$D$7) | P21: =$C$8+($D$8-$C$8)*$AD21 | Q21: =$C$9 | R21: =_xlfn.LOGNORM.INV($AF21,LN($C$10)-0.5*LN(1+($D$10/$C$10)^2),SQRT(LN(1+($D$10/$C$10)^2))) | S21: =SUM(M21:R21) | AA21: =RAND() | AB21: =RAND() | AC21: =RAND() | AD21: =RAND() | AE21: =RAND() | AF21: =RAND()
A22: P90 | B22: =_xlfn.PERCENTILE.INC($S$5:$S$5004,0.9) | M22: =_xlfn.BETA.INV($AA22,1+4*($D$5-$C$5)/($E$5-$C$5),1+4*($E$5-$D$5)/($E$5-$C$5),$C$5,$E$5) | N22: =IF($AB22<($D$6-$C$6)/($E$6-$C$6),$C$6+SQRT($AB22*($E$6-$C$6)*($D$6-$C$6)),$E$6-SQRT((1-$AB22)*($E$6-$C$6)*($E$6-$D$6))) | O22: =_xlfn.NORM.INV($AC22,$C$7,$D$7) | P22: =$C$8+($D$8-$C$8)*$AD22 | Q22: =$C$9 | R22: =_xlfn.LOGNORM.INV($AF22,LN($C$10)-0.5*LN(1+($D$10/$C$10)^2),SQRT(LN(1+($D$10/$C$10)^2))) | S22: =SUM(M22:R22) | AA22: =RAND() | AB22: =RAND() | AC22: =RAND() | AD22: =RAND() | AE22: =RAND() | AF22: =RAND()
A23: P95 | B23: =_xlfn.PERCENTILE.INC($S$5:$S$5004,0.95) | M23: =_xlfn.BETA.INV($AA23,1+4*($D$5-$C$5)/($E$5-$C$5),1+4*($E$5-$D$5)/($E$5-$C$5),$C$5,$E$5) | N23: =IF($AB23<($D$6-$C$6)/($E$6-$C$6),$C$6+SQRT($AB23*($E$6-$C$6)*($D$6-$C$6)),$E$6-SQRT((1-$AB23)*($E$6-$C$6)*($E$6-$D$6))) | O23: =_xlfn.NORM.INV($AC23,$C$7,$D$7) | P23: =$C$8+($D$8-$C$8)*$AD23 | Q23: =$C$9 | R23: =_xlfn.LOGNORM.INV($AF23,LN($C$10)-0.5*LN(1+($D$10/$C$10)^2),SQRT(LN(1+($D$10/$C$10)^2))) | S23: =SUM(M23:R23) | AA23: =RAND() | AB23: =RAND() | AC23: =RAND() | AD23: =RAND() | AE23: =RAND() | AF23: =RAND()
A24: Recommended @ 80% | B24: =_xlfn.PERCENTILE.INC($S$5:$S$5004,$I$7) | M24: =_xlfn.BETA.INV($AA24,1+4*($D$5-$C$5)/($E$5-$C$5),1+4*($E$5-$D$5)/($E$5-$C$5),$C$5,$E$5) | N24: =IF($AB24<($D$6-$C$6)/($E$6-$C$6),$C$6+SQRT($AB24*($E$6-$C$6)*($D$6-$C$6)),$E$6-SQRT((1-$AB24)*($E$6-$C$6)*($E$6-$D$6))) | O24: =_xlfn.NORM.INV($AC24,$C$7,$D$7) | P24: =$C$8+($D$8-$C$8)*$AD24 | Q24: =$C$9 | R24: =_xlfn.LOGNORM.INV($AF24,LN($C$10)-0.5*LN(1+($D$10/$C$10)^2),SQRT(LN(1+($D$10/$C$10)^2))) | S24: =SUM(M24:R24) | AA24: =RAND() | AB24: =RAND() | AC24: =RAND() | AD24: =RAND() | AE24: =RAND() | AF24: =RAND()
A25: Contingency vs base | B25: =_xlfn.PERCENTILE.INC($S$5:$S$5004,$I$7)-F11 | M25: =_xlfn.BETA.INV($AA25,1+4*($D$5-$C$5)/($E$5-$C$5),1+4*($E$5-$D$5)/($E$5-$C$5),$C$5,$E$5) | N25: =IF($AB25<($D$6-$C$6)/($E$6-$C$6),$C$6+SQRT($AB25*($E$6-$C$6)*($D$6-$C$6)),$E$6-SQRT((1-$AB25)*($E$6-$C$6)*($E$6-$D$6))) | O25: =_xlfn.NORM.INV($AC25,$C$7,$D$7) | P25: =$C$8+($D$8-$C$8)*$AD25 | Q25: =$C$9 | R25: =_xlfn.LOGNORM.INV($AF25,LN($C$10)-0.5*LN(1+($D$10/$C$10)^2),SQRT(LN(1+($D$10/$C$10)^2))) | S25: =SUM(M25:R25) | AA25: =RAND() | AB25: =RAND() | AC25: =RAND() | AD25: =RAND() | AE25: =RAND() | AF25: =RAND()
A26: P(cost <= budget) | B26: =COUNTIF($S$5:$S$5004,"<="&$I$6)/5000 | M26: =_xlfn.BETA.INV($AA26,1+4*($D$5-$C$5)/($E$5-$C$5),1+4*($E$5-$D$5)/($E$5-$C$5),$C$5,$E$5) | N26: =IF($AB26<($D$6-$C$6)/($E$6-$C$6),$C$6+SQRT($AB26*($E$6-$C$6)*($D$6-$C$6)),$E$6-SQRT((1-$AB26)*($E$6-$C$6)*($E$6-$D$6))) | O26: =_xlfn.NORM.INV($AC26,$C$7,$D$7) | P26: =$C$8+($D$8-$C$8)*$AD26 | Q26: =$C$9 | R26: =_xlfn.LOGNORM.INV($AF26,LN($C$10)-0.5*LN(1+($D$10/$C$10)^2),SQRT(LN(1+($D$10/$C$10)^2))) | S26: =SUM(M26:R26) | AA26: =RAND() | AB26: =RAND() | AC26: =RAND() | AD26: =RAND() | AE26: =RAND() | AF26: =RAND()
M27: =_xlfn.BETA.INV($AA27,1+4*($D$5-$C$5)/($E$5-$C$5),1+4*($E$5-$D$5)/($E$5-$C$5),$C$5,$E$5) | N27: =IF($AB27<($D$6-$C$6)/($E$6-$C$6),$C$6+SQRT($AB27*($E$6-$C$6)*($D$6-$C$6)),$E$6-SQRT((1-$AB27)*($E$6-$C$6)*($E$6-$D$6))) | O27: =_xlfn.NORM.INV($AC27,$C$7,$D$7) | P27: =$C$8+($D$8-$C$8)*$AD27 | Q27: =$C$9 | R27: =_xlfn.LOGNORM.INV($AF27,LN($C$10)-0.5*LN(1+($D$10/$C$10)^2),SQRT(LN(1+($D$10/$C$10)^2))) | S27: =SUM(M27:R27) | AA27: =RAND() | AB27: =RAND() | AC27: =RAND() | AD27: =RAND() | AE27: =RAND() | AF27: =RAND()
M28: =_xlfn.BETA.INV($AA28,1+4*($D$5-$C$5)/($E$5-$C$5),1+4*($E$5-$D$5)/($E$5-$C$5),$C$5,$E$5) | N28: =IF($AB28<($D$6-$C$6)/($E$6-$C$6),$C$6+SQRT($AB28*($E$6-$C$6)*($D$6-$C$6)),$E$6-SQRT((1-$AB28)*($E$6-$C$6)*($E$6-$D$6))) | O28: =_xlfn.NORM.INV($AC28,$C$7,$D$7) | P28: =$C$8+($D$8-$C$8)*$AD28 | Q28: =$C$9 | R28: =_xlfn.LOGNORM.INV($AF28,LN($C$10)-0.5*LN(1+($D$10/$C$10)^2),SQRT(LN(1+($D$10/$C$10)^2))) | S28: =SUM(M28:R28) | AA28: =RAND() | AB28: =RAND() | AC28: =RAND() | AD28: =RAND() | AE28: =RAND() | AF28: =RAND()
M29: =_xlfn.BETA.INV($AA29,1+4*($D$5-$C$5)/($E$5-$C$5),1+4*($E$5-$D$5)/($E$5-$C$5),$C$5,$E$5) | N29: =IF($AB29<($D$6-$C$6)/($E$6-$C$6),$C$6+SQRT($AB29*($E$6-$C$6)*($D$6-$C$6)),$E$6-SQRT((1-$AB29)*($E$6-$C$6)*($E$6-$D$6))) | O29: =_xlfn.NORM.INV($AC29,$C$7,$D$7) | P29: =$C$8+($D$8-$C$8)*$AD29 | Q29: =$C$9 | R29: =_xlfn.LOGNORM.INV($AF29,LN($C$10)-0.5*LN(1+($D$10/$C$10)^2),SQRT(LN(1+($D$10/$C$10)^2))) | S29: =SUM(M29:R29) | AA29: =RAND() | AB29: =RAND() | AC29: =RAND() | AD29: =RAND() | AE29: =RAND() | AF29: =RAND()
M30: =_xlfn.BETA.INV($AA30,1+4*($D$5-$C$5)/($E$5-$C$5),1+4*($E$5-$D$5)/($E$5-$C$5),$C$5,$E$5) | N30: =IF($AB30<($D$6-$C$6)/($E$6-$C$6),$C$6+SQRT($AB30*($E$6-$C$6)*($D$6-$C$6)),$E$6-SQRT((1-$AB30)*($E$6-$C$6)*($E$6-$D$6))) | O30: =_xlfn.NORM.INV($AC30,$C$7,$D$7) | P30: =$C$8+($D$8-$C$8)*$AD30 | Q30: =$C$9 | R30: =_xlfn.LOGNORM.INV($AF30,LN($C$10)-0.5*LN(1+($D$10/$C$10)^2),SQRT(LN(1+($D$10/$C$10)^2))) | S30: =SUM(M30:R30) | AA30: =RAND() | AB30: =RAND() | AC30: =RAND() | AD30: =RAND() | AE30: =RAND() | AF30: =RAND()
M31: =_xlfn.BETA.INV($AA31,1+4*($D$5-$C$5)/($E$5-$C$5),1+4*($E$5-$D$5)/($E$5-$C$5),$C$5,$E$5) | N31: =IF($AB31<($D$6-$C$6)/($E$6-$C$6),$C$6+SQRT($AB31*($E$6-$C$6)*($D$6-$C$6)),$E$6-SQRT((1-$AB31)*($E$6-$C$6)*($E$6-$D$6))) | O31: =_xlfn.NORM.INV($AC31,$C$7,$D$7) | P31: =$C$8+($D$8-$C$8)*$AD31 | Q31: =$C$9 | R31: =_xlfn.LOGNORM.INV($AF31,LN($C$10)-0.5*LN(1+($D$10/$C$10)^2),SQRT(LN(1+($D$10/$C$10)^2))) | S31: =SUM(M31:R31) | AA31: =RAND() | AB31: =RAND() | AC31: =RAND() | AD31: =RAND() | AE31: =RAND() | AF31: =RAND()
M32: =_xlfn.BETA.INV($AA32,1+4*($D$5-$C$5)/($E$5-$C$5),1+4*($E$5-$D$5)/($E$5-$C$5),$C$5,$E$5) | N32: =IF($AB32<($D$6-$C$6)/($E$6-$C$6),$C$6+SQRT($AB32*($E$6-$C$6)*($D$6-$C$6)),$E$6-SQRT((1-$AB32)*($E$6-$C$6)*($E$6-$D$6))) | O32: =_xlfn.NORM.INV($AC32,$C$7,$D$7) | P32: =$C$8+($D$8-$C$8)*$AD32 | Q32: =$C$9 | R32: =_xlfn.LOGNORM.INV($AF32,LN($C$10)-0.5*LN(1+($D$10/$C$10)^2),SQRT(LN(1+($D$10/$C$10)^2))) | S32: =SUM(M32:R32) | AA32: =RAND() | AB32: =RAND() | AC32: =RAND() | AD32: =RAND() | AE32: =RAND() | AF32: =RAND()
M33: =_xlfn.BETA.INV($AA33,1+4*($D$5-$C$5)/($E$5-$C$5),1+4*($E$5-$D$5)/($E$5-$C$5),$C$5,$E$5) | N33: =IF($AB33<($D$6-$C$6)/($E$6-$C$6),$C$6+SQRT($AB33*($E$6-$C$6)*($D$6-$C$6)),$E$6-SQRT((1-$AB33)*($E$6-$C$6)*($E$6-$D$6))) | O33: =_xlfn.NORM.INV($AC33,$C$7,$D$7) | P33: =$C$8+($D$8-$C$8)*$AD33 | Q33: =$C$9 | R33: =_xlfn.LOGNORM.INV($AF33,LN($C$10)-0.5*LN(1+($D$10/$C$10)^2),SQRT(LN(1+($D$10/$C$10)^2))) | S33: =SUM(M33:R33) | AA33: =RAND() | AB33: =RAND() | AC33: =RAND() | AD33: =RAND() | AE33: =RAND() | AF33: =RAND()
M34: =_xlfn.BETA.INV($AA34,1+4*($D$5-$C$5)/($E$5-$C$5),1+4*($E$5-$D$5)/($E$5-$C$5),$C$5,$E$5) | N34: =IF($AB34<($D$6-$C$6)/($E$6-$C$6),$C$6+SQRT($AB34*($E$6-$C$6)*($D$6-$C$6)),$E$6-SQRT((1-$AB34)*($E$6-$C$6)*($E$6-$D$6))) | O34: =_xlfn.NORM.INV($AC34,$C$7,$D$7) | P34: =$C$8+($D$8-$C$8)*$AD34 | Q34: =$C$9 | R34: =_xlfn.LOGNORM.INV($AF34,LN($C$10)-0.5*LN(1+($D$10/$C$10)^2),SQRT(LN(1+($D$10/$C$10)^2))) | S34: =SUM(M34:R34) | AA34: =RAND() | AB34: =RAND() | AC34: =RAND() | AD34: =RAND() | AE34: =RAND() | AF34: =RAND()
M35: =_xlfn.BETA.INV($AA35,1+4*($D$5-$C$5)/($E$5-$C$5),1+4*($E$5-$D$5)/($E$5-$C$5),$C$5,$E$5) | N35: =IF($AB35<($D$6-$C$6)/($E$6-$C$6),$C$6+SQRT($AB35*($E$6-$C$6)*($D$6-$C$6)),$E$6-SQRT((1-$AB35)*($E$6-$C$6)*($E$6-$D$6))) | O35: =_xlfn.NORM.INV($AC35,$C$7,$D$7) | P35: =$C$8+($D$8-$C$8)*$AD35 | Q35: =$C$9 | R35: =_xlfn.LOGNORM.INV($AF35,LN($C$10)-0.5*LN(1+($D$10/$C$10)^2),SQRT(LN(1+($D$10/$C$10)^2))) | S35: =SUM(M35:R35) | AA35: =RAND() | AB35: =RAND() | AC35: =RAND() | AD35: =RAND() | AE35: =RAND() | AF35: =RAND()
M36: =_xlfn.BETA.INV($AA36,1+4*($D$5-$C$5)/($E$5-$C$5),1+4*($E$5-$D$5)/($E$5-$C$5),$C$5,$E$5) | N36: =IF($AB36<($D$6-$C$6)/($E$6-$C$6),$C$6+SQRT($AB36*($E$6-$C$6)*($D$6-$C$6)),$E$6-SQRT((1-$AB36)*($E$6-$C$6)*($E$6-$D$6))) | O36: =_xlfn.NORM.INV($AC36,$C$7,$D$7) | P36: =$C$8+($D$8-$C$8)*$AD36 | Q36: =$C$9 | R36: =_xlfn.LOGNORM.INV($AF36,LN($C$10)-0.5*LN(1+($D$10/$C$10)^2),SQRT(LN(1+($D$10/$C$10)^2))) | S36: =SUM(M36:R36) | AA36: =RAND() | AB36: =RAND() | AC36: =RAND() | AD36: =RAND() | AE36: =RAND() | AF36: =RAND()
M37: =_xlfn.BETA.INV($AA37,1+4*($D$5-$C$5)/($E$5-$C$5),1+4*($E$5-$D$5)/($E$5-$C$5),$C$5,$E$5) | N37: =IF($AB37<($D$6-$C$6)/($E$6-$C$6),$C$6+SQRT($AB37*($E$6-$C$6)*($D$6-$C$6)),$E$6-SQRT((1-$AB37)*($E$6-$C$6)*($E$6-$D$6))) | O37: =_xlfn.NORM.INV($AC37,$C$7,$D$7) | P37: =$C$8+($D$8-$C$8)*$AD37 | Q37: =$C$9 | R37: =_xlfn.LOGNORM.INV($AF37,LN($C$10)-0.5*LN(1+($D$10/$C$10)^2),SQRT(LN(1+($D$10/$C$10)^2))) | S37: =SUM(M37:R37) | AA37: =RAND() | AB37: =RAND() | AC37: =RAND() | AD37: =RAND() | AE37: =RAND() | AF37: =RAND()
M38: =_xlfn.BETA.INV($AA38,1+4*($D$5-$C$5)/($E$5-$C$5),1+4*($E$5-$D$5)/($E$5-$C$5),$C$5,$E$5) | N38: =IF($AB38<($D$6-$C$6)/($E$6-$C$6),$C$6+SQRT($AB38*($E$6-$C$6)*($D$6-$C$6)),$E$6-SQRT((1-$AB38)*($E$6-$C$6)*($E$6-$D$6))) | O38: =_xlfn.NORM.INV($AC38,$C$7,$D$7) | P38: =$C$8+($D$8-$C$8)*$AD38 | Q38: =$C$9 | R38: =_xlfn.LOGNORM.INV($AF38,LN($C$10)-0.5*LN(1+($D$10/$C$10)^2),SQRT(LN(1+($D$10/$C$10)^2))) | S38: =SUM(M38:R38) | AA38: =RAND() | AB38: =RAND() | AC38: =RAND() | AD38: =RAND() | AE38: =RAND() | AF38: =RAND()
... M5004: =_xlfn.BETA.INV($AA5004,1+4*($D$5-$C$5)/($E$5-$C$5),1+4*($E$5-$D$5)/($E$5-$C$5),$C$5,$E$5) | N5004: =IF($AB5004<($D$6-$C$6)/($E$6-$C$6),$C$6+SQRT($AB5004*($E$6-$C$6)*($D$6-$C$6)),$E$6-SQRT((1-$AB5004)*($E$6-$C$6)*($E$6-$D$6))) | O5004: =_xlfn.NORM.INV($AC5004,$C$7,$D$7) | P5004: =$C$8+($D$8-$C$8)*$AD5004 | Q5004: =$C$9 | R5004: =_xlfn.LOGNORM.INV($AF5004,LN($C$10)-0.5*LN(1+($D$10/$C$10)^2),SQRT(LN(1+($D$10/$C$10)^2))) | S5004: =SUM(M5004:R5004) | AA5004: =RAND() | AB5004: =RAND() | AC5004: =RAND() | AD5004: =RAND() | AE5004: =RAND() | AF5004: =RAND()

Sheet Charts
A1: DISTRIBUTION OF TOTAL COST
A3: Bin # | B3: Low | C3: High | D3: Center | E3: Count
A4: 1 | B4: =MIN('Monte Carlo'!$S$5:$S$5004)+(0)*(MAX('Monte Carlo'!$S$5:$S$5004)-MIN('Monte Carlo'!$S$5:$S$5004))/30 | C4: =MIN('Monte Carlo'!$S$5:$S$5004)+(1)*(MAX('Monte Carlo'!$S$5:$S$5004)-MIN('Monte Carlo'!$S$5:$S$5004))/30 | D4: =(B4+C4)/2 | E4: =COUNTIF('Monte Carlo'!$S$5:$S$5004,"<"&C4)-COUNTIF('Monte Carlo'!$S$5:$S$5004,"<"&B4)
A5: 2 | B5: =MIN('Monte Carlo'!$S$5:$S$5004)+(1)*(MAX('Monte Carlo'!$S$5:$S$5004)-MIN('Monte Carlo'!$S$5:$S$5004))/30 | C5: =MIN('Monte Carlo'!$S$5:$S$5004)+(2)*(MAX('Monte Carlo'!$S$5:$S$5004)-MIN('Monte Carlo'!$S$5:$S$5004))/30 | D5: =(B5+C5)/2 | E5: =COUNTIF('Monte Carlo'!$S$5:$S$5004,"<"&C5)-COUNTIF('Monte Carlo'!$S$5:$S$5004,"<"&B5)
A6: 3 | B6: =MIN('Monte Carlo'!$S$5:$S$5004)+(2)*(MAX('Monte Carlo'!$S$5:$S$5004)-MIN('Monte Carlo'!$S$5:$S$5004))/30 | C6: =MIN('Monte Carlo'!$S$5:$S$5004)+(3)*(MAX('Monte Carlo'!$S$5:$S$5004)-MIN('Monte Carlo'!$S$5:$S$5004))/30 | D6: =(B6+C6)/2 | E6: =COUNTIF('Monte Carlo'!$S$5:$S$5004,"<"&C6)-COUNTIF('Monte Carlo'!$S$5:$S$5004,"<"&B6)
A7: 4 | B7: =MIN('Monte Carlo'!$S$5:$S$5004)+(3)*(MAX('Monte Carlo'!$S$5:$S$5004)-MIN('Monte Carlo'!$S$5:$S$5004))/30 | C7: =MIN('Monte Carlo'!$S$5:$S$5004)+(4)*(MAX('Monte Carlo'!$S$5:$S$5004)-MIN('Monte Carlo'!$S$5:$S$5004))/30 | D7: =(B7+C7)/2 | E7: =COUNTIF('Monte Carlo'!$S$5:$S$5004,"<"&C7)-COUNTIF('Monte Carlo'!$S$5:$S$5004,"<"&B7)
A8: 5 | B8: =MIN('Monte Carlo'!$S$5:$S$5004)+(4)*(MAX('Monte Carlo'!$S$5:$S$5004)-MIN('Monte Carlo'!$S$5:$S$5004))/30 | C8: =MIN('Monte Carlo'!$S$5:$S$5004)+(5)*(MAX('Monte Carlo'!$S$5:$S$5004)-MIN('Monte Carlo'!$S$5:$S$5004))/30 | D8: =(B8+C8)/2 | E8: =COUNTIF('Monte Carlo'!$S$5:$S$5004,"<"&C8)-COUNTIF('Monte Carlo'!$S$5:$S$5004,"<"&B8)
A9: 6 | B9: =MIN('Monte Carlo'!$S$5:$S$5004)+(5)*(MAX('Monte Carlo'!$S$5:$S$5004)-MIN('Monte Carlo'!$S$5:$S$5004))/30 | C9: =MIN('Monte Carlo'!$S$5:$S$5004)+(6)*(MAX('Monte Carlo'!$S$5:$S$5004)-MIN('Monte Carlo'!$S$5:$S$5004))/30 | D9: =(B9+C9)/2 | E9: =COUNTIF('Monte Carlo'!$S$5:$S$5004,"<"&C9)-COUNTIF('Monte Carlo'!$S$5:$S$5004,"<"&B9)
A10: 7 | B10: =MIN('Monte Carlo'!$S$5:$S$5004)+(6)*(MAX('Monte Carlo'!$S$5:$S$5004)-MIN('Monte Carlo'!$S$5:$S$5004))/30 | C10: =MIN('Monte Carlo'!$S$5:$S$5004)+(7)*(MAX('Monte Carlo'!$S$5:$S$5004)-MIN('Monte Carlo'!$S$5:$S$5004))/30 | D10: =(B10+C10)/2 | E10: =COUNTIF('Monte Carlo'!$S$5:$S$5004,"<"&C10)-COUNTIF('Monte Carlo'!$S$5:$S$5004,"<"&B10)
A11: 8 | B11: =MIN('Monte Carlo'!$S$5:$S$5004)+(7)*(MAX('Monte Carlo'!$S$5:$S$5004)-MIN('Monte Carlo'!$S$5:$S$5004))/30 | C11: =MIN('Monte Carlo'!$S$5:$S$5004)+(8)*(MAX('Monte Carlo'!$S$5:$S$5004)-MIN('Monte Carlo'!$S$5:$S$5004))/30 | D11: =(B11+C11)/2 | E11: =COUNTIF('Monte Carlo'!$S$5:$S$5004,"<"&C11)-COUNTIF('Monte Carlo'!$S$5:$S$5004,"<"&B11)
A12: 9 | B12: =MIN('Monte Carlo'!$S$5:$S$5004)+(8)*(MAX('Monte Carlo'!$S$5:$S$5004)-MIN('Monte Carlo'!$S$5:$S$5004))/30 | C12: =MIN('Monte Carlo'!$S$5:$S$5004)+(9)*(MAX('Monte Carlo'!$S$5:$S$5004)-MIN('Monte Carlo'!$S$5:$S$5004))/30 | D12: =(B12+C12)/2 | E12: =COUNTIF('Monte Carlo'!$S$5:$S$5004,"<"&C12)-COUNTIF('Monte Carlo'!$S$5:$S$5004,"<"&B12)
A13: 10 | B13: =MIN('Monte Carlo'!$S$5:$S$5004)+(9)*(MAX('Monte Carlo'!$S$5:$S$5004)-MIN('Monte Carlo'!$S$5:$S$5004))/30 | C13: =MIN('Monte Carlo'!$S$5:$S$5004)+(10)*(MAX('Monte Carlo'!$S$5:$S$5004)-MIN('Monte Carlo'!$S$5:$S$5004))/30 | D13: =(B13+C13)/2 | E13: =COUNTIF('Monte Carlo'!$S$5:$S$5004,"<"&C13)-COUNTIF('Monte Carlo'!$S$5:$S$5004,"<"&B13)
A14: 11 | B14: =MIN('Monte Carlo'!$S$5:$S$5004)+(10)*(MAX('Monte Carlo'!$S$5:$S$5004)-MIN('Monte Carlo'!$S$5:$S$5004))/30 | C14: =MIN('Monte Carlo'!$S$5:$S$5004)+(11)*(MAX('Monte Carlo'!$S$5:$S$5004)-MIN('Monte Carlo'!$S$5:$S$5004))/30 | D14: =(B14+C14)/2 | E14: =COUNTIF('Monte Carlo'!$S$5:$S$5004,"<"&C14)-COUNTIF('Monte Carlo'!$S$5:$S$5004,"<"&B14)
A15: 12 | B15: =MIN('Monte Carlo'!$S$5:$S$5004)+(11)*(MAX('Monte Carlo'!$S$5:$S$5004)-MIN('Monte Carlo'!$S$5:$S$5004))/30 | C15: =MIN('Monte Carlo'!$S$5:$S$5004)+(12)*(MAX('Monte Carlo'!$S$5:$S$5004)-MIN('Monte Carlo'!$S$5:$S$5004))/30 | D15: =(B15+C15)/2 | E15: =COUNTIF('Monte Carlo'!$S$5:$S$5004,"<"&C15)-COUNTIF('Monte Carlo'!$S$5:$S$5004,"<"&B15)
A16: 13 | B16: =MIN('Monte Carlo'!$S$5:$S$5004)+(12)*(MAX('Monte Carlo'!$S$5:$S$5004)-MIN('Monte Carlo'!$S$5:$S$5004))/30 | C16: =MIN('Monte Carlo'!$S$5:$S$5004)+(13)*(MAX('Monte Carlo'!$S$5:$S$5004)-MIN('Monte Carlo'!$S$5:$S$5004))/30 | D16: =(B16+C16)/2 | E16: =COUNTIF('Monte Carlo'!$S$5:$S$5004,"<"&C16)-COUNTIF('Monte Carlo'!$S$5:$S$5004,"<"&B16)
A17: 14 | B17: =MIN('Monte Carlo'!$S$5:$S$5004)+(13)*(MAX('Monte Carlo'!$S$5:$S$5004)-MIN('Monte Carlo'!$S$5:$S$5004))/30 | C17: =MIN('Monte Carlo'!$S$5:$S$5004)+(14)*(MAX('Monte Carlo'!$S$5:$S$5004)-MIN('Monte Carlo'!$S$5:$S$5004))/30 | D17: =(B17+C17)/2 | E17: =COUNTIF('Monte Carlo'!$S$5:$S$5004,"<"&C17)-COUNTIF('Monte Carlo'!$S$5:$S$5004,"<"&B17)
A18: 15 | B18: =MIN('Monte Carlo'!$S$5:$S$5004)+(14)*(MAX('Monte Carlo'!$S$5:$S$5004)-MIN('Monte Carlo'!$S$5:$S$5004))/30 | C18: =MIN('Monte Carlo'!$S$5:$S$5004)+(15)*(MAX('Monte Carlo'!$S$5:$S$5004)-MIN('Monte Carlo'!$S$5:$S$5004))/30 | D18: =(B18+C18)/2 | E18: =COUNTIF('Monte Carlo'!$S$5:$S$5004,"<"&C18)-COUNTIF('Monte Carlo'!$S$5:$S$5004,"<"&B18)
A19: 16 | B19: =MIN('Monte Carlo'!$S$5:$S$5004)+(15)*(MAX('Monte Carlo'!$S$5:$S$5004)-MIN('Monte Carlo'!$S$5:$S$5004))/30 | C19: =MIN('Monte Carlo'!$S$5:$S$5004)+(16)*(MAX('Monte Carlo'!$S$5:$S$5004)-MIN('Monte Carlo'!$S$5:$S$5004))/30 | D19: =(B19+C19)/2 | E19: =COUNTIF('Monte Carlo'!$S$5:$S$5004,"<"&C19)-COUNTIF('Monte Carlo'!$S$5:$S$5004,"<"&B19)
A20: 17 | B20: =MIN('Monte Carlo'!$S$5:$S$5004)+(16)*(MAX('Monte Carlo'!$S$5:$S$5004)-MIN('Monte Carlo'!$S$5:$S$5004))/30 | C20: =MIN('Monte Carlo'!$S$5:$S$5004)+(17)*(MAX('Monte Carlo'!$S$5:$S$5004)-MIN('Monte Carlo'!$S$5:$S$5004))/30 | D20: =(B20+C20)/2 | E20: =COUNTIF('Monte Carlo'!$S$5:$S$5004,"<"&C20)-COUNTIF('Monte Carlo'!$S$5:$S$5004,"<"&B20)
A21: 18 | B21: =MIN('Monte Carlo'!$S$5:$S$5004)+(17)*(MAX('Monte Carlo'!$S$5:$S$5004)-MIN('Monte Carlo'!$S$5:$S$5004))/30 | C21: =MIN('Monte Carlo'!$S$5:$S$5004)+(18)*(MAX('Monte Carlo'!$S$5:$S$5004)-MIN('Monte Carlo'!$S$5:$S$5004))/30 | D21: =(B21+C21)/2 | E21: =COUNTIF('Monte Carlo'!$S$5:$S$5004,"<"&C21)-COUNTIF('Monte Carlo'!$S$5:$S$5004,"<"&B21)
A22: 19 | B22: =MIN('Monte Carlo'!$S$5:$S$5004)+(18)*(MAX('Monte Carlo'!$S$5:$S$5004)-MIN('Monte Carlo'!$S$5:$S$5004))/30 | C22: =MIN('Monte Carlo'!$S$5:$S$5004)+(19)*(MAX('Monte Carlo'!$S$5:$S$5004)-MIN('Monte Carlo'!$S$5:$S$5004))/30 | D22: =(B22+C22)/2 | E22: =COUNTIF('Monte Carlo'!$S$5:$S$5004,"<"&C22)-COUNTIF('Monte Carlo'!$S$5:$S$5004,"<"&B22)
A23: 20 | B23: =MIN('Monte Carlo'!$S$5:$S$5004)+(19)*(MAX('Monte Carlo'!$S$5:$S$5004)-MIN('Monte Carlo'!$S$5:$S$5004))/30 | C23: =MIN('Monte Carlo'!$S$5:$S$5004)+(20)*(MAX('Monte Carlo'!$S$5:$S$5004)-MIN('Monte Carlo'!$S$5:$S$5004))/30 | D23: =(B23+C23)/2 | E23: =COUNTIF('Monte Carlo'!$S$5:$S$5004,"<"&C23)-COUNTIF('Monte Carlo'!$S$5:$S$5004,"<"&B23)
A24: 21 | B24: =MIN('Monte Carlo'!$S$5:$S$5004)+(20)*(MAX('Monte Carlo'!$S$5:$S$5004)-MIN('Monte Carlo'!$S$5:$S$5004))/30 | C24: =MIN('Monte Carlo'!$S$5:$S$5004)+(21)*(MAX('Monte Carlo'!$S$5:$S$5004)-MIN('Monte Carlo'!$S$5:$S$5004))/30 | D24: =(B24+C24)/2 | E24: =COUNTIF('Monte Carlo'!$S$5:$S$5004,"<"&C24)-COUNTIF('Monte Carlo'!$S$5:$S$5004,"<"&B24)
A25: 22 | B25: =MIN('Monte Carlo'!$S$5:$S$5004)+(21)*(MAX('Monte Carlo'!$S$5:$S$5004)-MIN('Monte Carlo'!$S$5:$S$5004))/30 | C25: =MIN('Monte Carlo'!$S$5:$S$5004)+(22)*(MAX('Monte Carlo'!$S$5:$S$5004)-MIN('Monte Carlo'!$S$5:$S$5004))/30 | D25: =(B25+C25)/2 | E25: =COUNTIF('Monte Carlo'!$S$5:$S$5004,"<"&C25)-COUNTIF('Monte Carlo'!$S$5:$S$5004,"<"&B25)
A26: 23 | B26: =MIN('Monte Carlo'!$S$5:$S$5004)+(22)*(MAX('Monte Carlo'!$S$5:$S$5004)-MIN('Monte Carlo'!$S$5:$S$5004))/30 | C26: =MIN('Monte Carlo'!$S$5:$S$5004)+(23)*(MAX('Monte Carlo'!$S$5:$S$5004)-MIN('Monte Carlo'!$S$5:$S$5004))/30 | D26: =(B26+C26)/2 | E26: =COUNTIF('Monte Carlo'!$S$5:$S$5004,"<"&C26)-COUNTIF('Monte Carlo'!$S$5:$S$5004,"<"&B26)
A27: 24 | B27: =MIN('Monte Carlo'!$S$5:$S$5004)+(23)*(MAX('Monte Carlo'!$S$5:$S$5004)-MIN('Monte Carlo'!$S$5:$S$5004))/30 | C27: =MIN('Monte Carlo'!$S$5:$S$5004)+(24)*(MAX('Monte Carlo'!$S$5:$S$5004)-MIN('Monte Carlo'!$S$5:$S$5004))/30 | D27: =(B27+C27)/2 | E27: =COUNTIF('Monte Carlo'!$S$5:$S$5004,"<"&C27)-COUNTIF('Monte Carlo'!$S$5:$S$5004,"<"&B27)
A28: 25 | B28: =MIN('Monte Carlo'!$S$5:$S$5004)+(24)*(MAX('Monte Carlo'!$S$5:$S$5004)-MIN('Monte Carlo'!$S$5:$S$5004))/30 | C28: =MIN('Monte Carlo'!$S$5:$S$5004)+(25)*(MAX('Monte Carlo'!$S$5:$S$5004)-MIN('Monte Carlo'!$S$5:$S$5004))/30 | D28: =(B28+C28)/2 | E28: =COUNTIF('Monte Carlo'!$S$5:$S$5004,"<"&C28)-COUNTIF('Monte Carlo'!$S$5:$S$5004,"<"&B28)
A29: 26 | B29: =MIN('Monte Carlo'!$S$5:$S$5004)+(25)*(MAX('Monte Carlo'!$S$5:$S$5004)-MIN('Monte Carlo'!$S$5:$S$5004))/30 | C29: =MIN('Monte Carlo'!$S$5:$S$5004)+(26)*(MAX('Monte Carlo'!$S$5:$S$5004)-MIN('Monte Carlo'!$S$5:$S$5004))/30 | D29: =(B29+C29)/2 | E29: =COUNTIF('Monte Carlo'!$S$5:$S$5004,"<"&C29)-COUNTIF('Monte Carlo'!$S$5:$S$5004,"<"&B29)
A30: 27 | B30: =MIN('Monte Carlo'!$S$5:$S$5004)+(26)*(MAX('Monte Carlo'!$S$5:$S$5004)-MIN('Monte Carlo'!$S$5:$S$5004))/30 | C30: =MIN('Monte Carlo'!$S$5:$S$5004)+(27)*(MAX('Monte Carlo'!$S$5:$S$5004)-MIN('Monte Carlo'!$S$5:$S$5004))/30 | D30: =(B30+C30)/2 | E30: =COUNTIF('Monte Carlo'!$S$5:$S$5004,"<"&C30)-COUNTIF('Monte Carlo'!$S$5:$S$5004,"<"&B30)
A31: 28 | B31: =MIN('Monte Carlo'!$S$5:$S$5004)+(27)*(MAX('Monte Carlo'!$S$5:$S$5004)-MIN('Monte Carlo'!$S$5:$S$5004))/30 | C31: =MIN('Monte Carlo'!$S$5:$S$5004)+(28)*(MAX('Monte Carlo'!$S$5:$S$5004)-MIN('Monte Carlo'!$S$5:$S$5004))/30 | D31: =(B31+C31)/2 | E31: =COUNTIF('Monte Carlo'!$S$5:$S$5004,"<"&C31)-COUNTIF('Monte Carlo'!$S$5:$S$5004,"<"&B31)
A32: 29 | B32: =MIN('Monte Carlo'!$S$5:$S$5004)+(28)*(MAX('Monte Carlo'!$S$5:$S$5004)-MIN('Monte Carlo'!$S$5:$S$5004))/30 | C32: =MIN('Monte Carlo'!$S$5:$S$5004)+(29)*(MAX('Monte Carlo'!$S$5:$S$5004)-MIN('Monte Carlo'!$S$5:$S$5004))/30 | D32: =(B32+C32)/2 | E32: =COUNTIF('Monte Carlo'!$S$5:$S$5004,"<"&C32)-COUNTIF('Monte Carlo'!$S$5:$S$5004,"<"&B32)
A33: 30 | B33: =MIN('Monte Carlo'!$S$5:$S$5004)+(29)*(MAX('Monte Carlo'!$S$5:$S$5004)-MIN('Monte Carlo'!$S$5:$S$5004))/30 | C33: =MIN('Monte Carlo'!$S$5:$S$5004)+(30)*(MAX('Monte Carlo'!$S$5:$S$5004)-MIN('Monte Carlo'!$S$5:$S$5004))/30 | D33: =(B33+C33)/2 | E33: =COUNTIF('Monte Carlo'!$S$5:$S$5004,"<"&C33)-COUNTIF('Monte Carlo'!$S$5:$S$5004,"<"&B33)
A40: CUMULATIVE PROBABILITY (S-CURVE)
A42: Cumulative % | B42: Total cost
A43: 0 | B43: =_xlfn.PERCENTILE.INC('Monte Carlo'!$S$5:$S$5004,A43)
A44: 0.05 | B44: =_xlfn.PERCENTILE.INC('Monte Carlo'!$S$5:$S$5004,A44)
A45: 0.1 | B45: =_xlfn.PERCENTILE.INC('Monte Carlo'!$S$5:$S$5004,A45)
A46: 0.15 | B46: =_xlfn.PERCENTILE.INC('Monte Carlo'!$S$5:$S$5004,A46)
A47: 0.2 | B47: =_xlfn.PERCENTILE.INC('Monte Carlo'!$S$5:$S$5004,A47)
A48: 0.25 | B48: =_xlfn.PERCENTILE.INC('Monte Carlo'!$S$5:$S$5004,A48)
...

Sheet How to Use
A1: MONTE CARLO COST MODEL — HOW IT WORKS
A3: 1. Go to the 'Monte Carlo' sheet.
A4: Edit the YELLOW cells in the input table (P1/P2/P3) and the Budget/Confidence.
A5: Each item samples from its distribution using the parameters you enter:
A6: fixed P1 = value
A7: uniform P1 = min, P2 = max
A8: triangular P1 = min, P2 = most likely, P3 = max
A9: pert P1 = min, P2 = most likely, P3 = max
A10: normal P1 = mean, P2 = std dev
A11: lognormal P1 = mean, P2 = std dev
A13: 2. Press F9 to re-roll all iterations. The SUMMARY and the charts update live.
A14: (The model is volatile: it also re-rolls on any edit.)
... A27: → requires Excel 2010 or newer (also works in LibreOffice Calc).
