Workbook
Name Affordability: _REF!$B$2:$B$5
Name Needs: _REF!$A$2:$A$3

Sheet Overview
A1: متابعة مشاريع Waves
A4: رقم المشروع | B4: اسم المشروع | C4: الموجة | D4: المختص | E4: المرحلة الحالية | F4: المخرجات | G4: التحديث | H4: الملاحظة | I4: الحالة
A5: SS-01 | B5: ='SS-01'!B4 -> توفير مواد خام وقطع الغيار لمطابع وزارة الدفاع (اتفاقية اطارية) | C5: 1 | D5: ='SS-01'!B5 -> عادل الحمياني | E5: =IFERROR(LOOKUP(2,1/('SS-01'!C13:C72<>""),'SS-01'!C13:C72),"—") -> 4 - Tender Pack Development | F5: =IFERROR(LOOKUP(2,1/('SS-01'!D13:D72<>""),'SS-01'!D13:D72),"—") -> Detailed LCCE | G5: =IFERROR(LOOKUP(2,1/('SS-01'!E13:E72<>""),'SS-01'!E13:E72),"—") -> لايوجد أي جراء على مقدر التكلفة | H5: =IFERROR(LOOKUP(2,1/('SS-01'!F13:F72<>""),'SS-01'!F13:F72),"—") -> الان في مرحلة اعداد الكراسة من قبل مدير المشروع | I5: =IFERROR(LOOKUP(2,1/('SS-01'!G13:G72<>""),'SS-01'!G13:G72),"—") -> مكتمل
A6: SS-02 | B6: ='SS-02'!B4 -> توريد وتخديم المواد الغذائية لمرافق الأندية والضيافات بالمنطقة الوسطى | C6: 1 | D6: ='SS-02'!B5 -> محمد الطويرش | E6: =IFERROR(LOOKUP(2,1/('SS-02'!C13:C74<>""),'SS-02'!C13:C74),"—") -> 4 - Tender Pack Development | F6: =IFERROR(LOOKUP(2,1/('SS-02'!D13:D72<>""),'SS-02'!D13:D72),"—") -> Independent LCCE | G6: =IFERROR(LOOKUP(2,1/('SS-02'!E13:E74<>""),'SS-02'!E13:E74),"—") -> الانتهاء من تعبئة النوذج، وانتظار الموافقه من قبل المدير المباشر لمدير المشروع | H6: =IFERROR(LOOKUP(2,1/('SS-02'!F13:F74<>""),'SS-02'!F13:F74),"—") -> تم إعطاء الملاظات النهائية على النموذج من قبل مدير المشروع ، بالاظافة الى ان النموذج لم يتم التسليم الى الان وينتظر اطلاع الإدارة عليه واعطائه الموفقه على المدخلات والملاحظات على نموذج استراتيجية التوريد. | I6: =IFERROR(LOOKUP(2,1/('SS-02'!G13:G72<>""),'SS-02'!G13:G72),"—") -> متأخر
A7: SS-03 | B7: ='SS-03'!B4 -> بدلة الكشف وبدلة الإزالة لصالح القوات البرية | C7: 1 | D7: ='SS-03'!B5 -> محمد اليوسف | E7: =IFERROR(LOOKUP(2,1/('SS-03'!C13:C72<>""),'SS-03'!C13:C72),"—") -> 3 - Affordability Estimate | F7: =IFERROR(LOOKUP(2,1/('SS-03'!D13:D72<>""),'SS-03'!D13:D72),"—") -> TCO | G7: =IFERROR(LOOKUP(2,1/('SS-03'!E13:E72<>""),'SS-03'!E13:E72),"—") -> لايوجد | H7: =IFERROR(LOOKUP(2,1/('SS-03'!F13:F72<>""),'SS-03'!F13:F72),"—") -> لازال مدير المشروع يعمل مع المستفيد النهائي على المتطلبات بالتنسيق مع فريق ديلويت | I7: =IFERROR(LOOKUP(2,1/('SS-03'!G13:G72<>""),'SS-03'!G13:G72),"—") -> متأخر
A8: SS-04 | B8: ='SS-04'!B4 -> تأمين ملبوسات عسكرية لكليه الدفاع الجوي من الاتفاقية الاطارية | C8: 2 | D8: ='SS-04'!B5 -> هيا المهنا | E8: =IFERROR(LOOKUP(2,1/('SS-04'!C13:C72<>""),'SS-04'!C13:C72),"—") -> 8 - Contract Execution | F8: =IFERROR(LOOKUP(2,1/('SS-04'!D13:D72<>""),'SS-04'!D13:D72),"—") -> — | G8: =IFERROR(LOOKUP(2,1/('SS-04'!E13:E72<>""),'SS-04'!E13:E72),"—") -> المشروع اتفاقية اطارية وبمرحلة تنفيذ العقد ولا يوجد متطلب على إدارة التكاليف | H8: =IFERROR(LOOKUP(2,1/('SS-04'!F13:F72<>""),'SS-04'!F13:F72),"—") -> تم اشراك إدارة التكاليف بالمشروع من مرحلة تنفيذ العقد ولا يتطلب مخرجات على إدارة التكاليف | I8: =IFERROR(LOOKUP(2,1/('SS-04'!G13:G72<>""),'SS-04'!G13:G72),"—") -> مكتمل
A9: SS-05 | B9: ='SS-05'!B4 -> معدات تغطية إعلامية شاملة | C9: 2 | D9: ='SS-05'!B5 -> محمد اليوسف | E9: =IFERROR(LOOKUP(2,1/('SS-05'!C13:C72<>""),'SS-05'!C13:C72),"—") -> 2 - Needs Identification | F9: =IFERROR(LOOKUP(2,1/('SS-05'!D13:D72<>""),'SS-05'!D13:D72),"—") -> — | G9: =IFERROR(LOOKUP(2,1/('SS-05'!E13:E72<>""),'SS-05'!E13:E72),"—") -> لم يتم بدء دور إدارة التكاليف حتى الآن بناءا على التنسيق مع إدارة المحافظ | H9: =IFERROR(LOOKUP(2,1/('SS-05'!F13:F72<>""),'SS-05'!F13:F72),"—") -> طلب من الجهة المستفيدة مراجعة جودة المدخلات | I9: =IFERROR(LOOKUP(2,1/('SS-05'!G13:G72<>""),'SS-05'!G13:G72),"—") -> على المسار
A10: SS-06 | B10: ='SS-06'!B4 -> رشاش عيار 40 ام كي 19 مع ملحقاته | C10: 2 | D10: ='SS-06'!B5 -> هيا المهنا | E10: =IFERROR(LOOKUP(2,1/('SS-06'!C13:C72<>""),'SS-06'!C13:C72),"—") -> 2 - Needs Identification | F10: =IFERROR(LOOKUP(2,1/('SS-06'!D13:D72<>""),'SS-06'!D13:D72),"—") -> — | G10: =IFERROR(LOOKUP(2,1/('SS-06'!E13:E72<>""),'SS-06'!E13:E72),"—") -> لا يوجد متطلب على إدارة التكاليف حتى الان | H10: =IFERROR(LOOKUP(2,1/('SS-06'!F13:F72<>""),'SS-06'!F13:F72),"—") -> تعبئة نموذج الافتراضات (MDAL) من قبل مدير المشروع للانتقال للخطوات القادمة | I10: =IFERROR(LOOKUP(2,1/('SS-06'!G13:G72<>""),'SS-06'!G13:G72),"—") -> على المسار
A11: SS-07 | B11: ='SS-07'!B4 -> تقديم الخدمات الاستشارية الفنية للحصول على شهادات | C11: 2 | D11: ='SS-07'!B5 -> عبدالله النويصر | E11: =IFERROR(LOOKUP(2,1/('SS-07'!C13:C72<>""),'SS-07'!C13:C72),"—") -> 8 - Contract Execution | F11: =IFERROR(LOOKUP(2,1/('SS-07'!D13:D72<>""),'SS-07'!D13:D72),"—") -> — | G11: =IFERROR(LOOKUP(2,1/('SS-07'!E13:E72<>""),'SS-07'!E13:E72),"—") -> — | H11: =IFERROR(LOOKUP(2,1/('SS-07'!F13:F72<>""),'SS-07'!F13:F72),"—") -> تم اشراك إدارة التكاليف بالمشروع من مرحلة تنفيذ العقد ولا يتطلب مخرجات على إدارة التكاليف | I11: =IFERROR(LOOKUP(2,1/('SS-07'!G13:G72<>""),'SS-07'!G13:G72),"—") -> مكتمل

Sheet ISSUES
A1: سجل المعوقات
A3: ت | B3: وصف المعوق | C3: المرحلة المتأثرة | D3: التأثير | E3: المسؤول | F3: الحالة | G3: تاريخ البداية | H3: تاريخ المعالجة
A4: 1
A5: 2
A6: 3
A7: 4
A8: 5
A9: 6
A10: 7
A11: 8
A12: 9
A13: 10
A14: 11
A15: 12
... A53: 50

Sheet Project Log
A1: سجل المشروع
A3: ت | B3: تاريخ الملاحظة | C3: تاريخ الانتهاء | D3: وصف المهمة | E3: الإجراء المطلوب | F3: التحديث | G3: المسؤول
A4: 1
A5: 2
A6: 3
A7: 4
A8: 5
A9: 6
A10: 7
A11: 8
A12: 9
A13: 10
A14: 11
A15: 12
... A53: 50

Sheet SS-01
A1: =IF(B4="","PP-01",B4) -> توفير مواد خام وقطع الغيار لمطابع وزارة الدفاع (اتفاقية اطارية)
A3: معلومات المشروع
A4: اسم المشروع | B4: توفير مواد خام وقطع الغيار لمطابع وزارة الدفاع (اتفاقية اطارية)
A5: المختص | B5: عادل الحمياني | C5: الإدارة | D5: SS
A7: الحالة | E7: بداية مرحلة Needs Identifications
A8: المرحلة الحالية | B8: =IFERROR(LOOKUP(2,1/(C13:C72<>""),C13:C72),"—") -> 4 - Tender Pack Development | E8: نهاية مرحلة Need Identifications
A9: تاريخ تحديث | B9: =IFERROR(LOOKUP(2,1/(B13:B72<>""),B13:B72),"—") -> 46180 | E9: بداية مرحلة Affordability Estimate
A10: التحديث | B10: =IFERROR(INDEX(E13:E72,MATCH(MAX(B13:B72),B13:B72,0)),"—") -> لايوجد أي جراء على مقدر التكلفة | E10: نهاية مرحلة Affordability Estimate
A11: سجل سير المشروع
A12: تسلسل | B12: التاريخ | C12: مرحلة سلسلة القيمة | D12: المخرجات | E12: التحديث | F12: ملاحظات | G12: الحالة
A13: 1 | B13: 46082 | C13: 3 - Affordability Estimate | D13: Detailed LCCE | E13: تم تزويدنا بملف الأسعار والكميات المتوقعة للمشروع | G13: مكتمل
A14: 2 | B14: 46086 | C14: 3 - Affordability Estimate | D14: Detailed LCCE | E14: تم ارسال ايميل لمدير المشروع بعدم وجود تفاصيل كافية | F14: 1. البنود في الورق والرول من (102الى 105) لم يتم ذكر الكميات المطلوبة 2. البنود في قطع غيار الصيانة من (296الى 297) لم يتم ذكر تفاصيل كافية لدراسة البند | G14: مكتمل
A15: 3 | B15: 46092 | C15: 3 - Affordability Estimate | D15: Detailed LCCE | E15: تم تزويدنا بقائمة الافتراضات | G15: مكتمل
A16: 4 | B16: 46111 | C16: 3 - Affordability Estimate | D16: Detailed LCCE | E16: تم تزويدنا بأتفاقية اطارية جديدة وبنود جديدة | F16: إعادة تعيين اغلب البنود في جداول الكميات | G16: مكتمل
A17: 5 | B17: 46112 | C17: 3 - Affordability Estimate | D17: Detailed LCCE | E17: تم ارسال ايميل لمدير المشروع بوجود ملاحظات على الكراسة | G17: مكتمل
A18: 6 | B18: 46112 | C18: 3 - Affordability Estimate | D18: Detailed LCCE | E18: تم تزويدنا بالكميات المتوقعة | G18: مكتمل
A19: 7 | B19: 46112 | C19: 3 - Affordability Estimate | D19: Detailed LCCE | E19: مناقشة نموذج LCCE مع مدير المشروع | F19: عدم وجود ملاحظات على النموذج | G19: مكتمل
A20: 8 | B20: 46114 | C20: 3 - Affordability Estimate | D20: Validation | E20: تم المناقشة والمراجعة مع الزميلة منال والموافقة ماجاء في نموذج LCCE | G20: مكتمل
A21: 9 | B21: 46118 | C21: 3 - Affordability Estimate | D21: Detailed LCCE | E21: تم ارسال LCCE لمدير المشروع | G21: مكتمل
A22: 10 | B22: 46119 | C22: 3 - Affordability Estimate | D22: Detailed LCCE | E22: تم تزويدنا بأيميل من مدير المشروع بعدم وجود ملاحظات على نموذج LCCE | G22: مكتمل
A23: 11 | B23: 46121 | C23: 3 - Affordability Estimate | D23: Independent LCCE | E23: تم استقبال ايميل من قبل مدير المشروع يطلب فية عمل نموذج LCCE مستقل ان تطلب الامر | G23: مكتمل
A24: 12 | B24: 46124 | C24: 3 - Affordability Estimate | D24: Independent LCCE | E24: ارسال لمدير المشروع ايميل بعدم الحاجة الى عمل نموذج LCCE مستقل | G24: مكتمل
A25: 13 | B25: 46126 | C25: 3 - Affordability Estimate | D25: TCO | E25: طلب مدير المشروع عمل TCO | F25: تم توضيح من قبل مدير المشروع بعدم وجود أي تكاليف إضافية بعد التواصل مع الجهة المستفيدة | G25: مكتمل
A26: 14 | B26: 46128 | C26: 3 - Affordability Estimate | D26: TCO | E26: تم ارسال نموذج TCO | F26: تم تذكر بان تكلفة LCCE مساوية لي تكلفة TCO وذلك لعدم وجود أي تكاليف إضافية | G26: مكتمل
A27: 15 | B27: 46145 | C27: 3 - Affordability Estimate | D27: Detailed LCCE | E27: بانتظار تأييد الجهة المستفيدة لـLCCE | G27: مكتمل
A28: 16 | B28: 46152 | C28: 3 - Affordability Estimate | D28: Detailed LCCE | E28: تم تأكيد بعدم وجود أي ملاحظات على LCCE من الجهة المستفيدة | F28: باجتماع اليوم كان رد مدير المشروع بان الجهة المستفيدة لا توجد لديها أي ملاحظات على نموذج LCCE بالإضافة الى عدم وجود أي اختلاف في الارتباط المالي مقارنة بالتكلفة التقديرية الأولية . | G28: مكتمل
A29: 17 | B29: 46156 | C29: 4 - Tender Pack Development | D29: Detailed LCCE | E29: لم يتم حضور الاجتماع | F29: لم يتم حضور الاجتماع | G29: مكتمل
A30: 18 | B30: 46180 | C30: 4 - Tender Pack Development | D30: Detailed LCCE | E30: لايوجد أي جراء على مقدر التكلفة | F30: الان في مرحلة اعداد الكراسة من قبل مدير المشروع | G30: مكتمل
A31: 19
A32: 20
A33: 21
A34: 22
A35: 23
A36: 24
A37: 25
A38: 26
A39: 27
A40: 28
A41: 29
A42: 30
...

Sheet SS-02
A1: =IF(B4="","PP-02",B4) -> توريد وتخديم المواد الغذائية لمرافق الأندية والضيافات بالمنطقة الوسطى
A3: معلومات المشروع
A4: اسم المشروع | B4: توريد وتخديم المواد الغذائية لمرافق الأندية والضيافات بالمنطقة الوسطى
A5: المختص | B5: محمد الطويرش | C5: الإدارة | D5: SS
A7: الحالة | E7: بداية مرحلة Needs Identifications
A8: المرحلة الحالية | B8: =IFERROR(LOOKUP(2,1/(C13:C74<>""),C13:C74),"—") -> 4 - Tender Pack Development | E8: نهاية مرحلة Need Identifications
A9: تاريخ تحديث | B9: =IFERROR(LOOKUP(2,1/(B13:B74<>""),B13:B74),"—") -> 46191 | E9: بداية مرحلة Affordability Estimate
A10: التحديث | B10: =IFERROR(INDEX(E13:E74,MATCH(MAX(B13:B74),B13:B74,0)),"—") -> الانتهاء من تعبئة النوذج، وانتظار الموافقه من قبل المدير المباشر لمدير المشروع | E10: نهاية مرحلة Affordability Estimate
A11: سجل سير المشروع
A12: تسلسل | B12: التاريخ | C12: مرحلة سلسلة القيمة | D12: المخرجات | E12: التحديث | F12: ملاحظات | G12: الحالة
A13: 1 | B13: 46092 | C13: 3 - Affordability Estimate | D13: Detailed LCCE | E13: تم ارسال نموذج LCCEالى مدير المشروع للاطلاع وابداء الملاظات على LCCE | G13: مكتمل
A14: 2 | B14: 46093 | C14: 3 - Affordability Estimate | D14: Detailed LCCE | E14: تم تأكيد نموذج LCCE من قبل مدير المشروع بعدم وجود أي ملاحظات | G14: مكتمل
A15: 3 | B15: 46093 | C15: 3 - Affordability Estimate | D15: Validation | E15: تم مناقشة مع الأستاذة منال وتم التأكيد والتدقيق على LCCE | G15: مكتمل
A16: 4 | B16: 46124 | C16: 3 - Affordability Estimate | D16: Detailed LCCE | E16: تم إضافة بند وطلب تحديثة على نموذج LCCE | F16: طلب إضافة بند (الذبائح) ضمن بنود المشروع | G16: مكتمل
A17: 5 | B17: 46133 | C17: 3 - Affordability Estimate | D17: Detailed LCCE | E17: تم ارسال نموذج LCCE بعد إضافة البند | G17: مكتمل
A18: 6 | B18: 46134 | C18: 3 - Affordability Estimate | D18: Validation | E18: تم مناقشة مع الأستاذة منال وتم التأكيد والتدقيق على LCCE بعد إضافة البند المحدث | G18: مكتمل
A19: 7 | B19: 46139 | C19: 3 - Affordability Estimate | D19: Independent LCCE | E19: تم ارسال طلب من قبل مدير المشروع لطلب نموذج LCCE مستقل | G19: مكتمل
A20: 8 | B20: 46139 | C20: 3 - Affordability Estimate | D20: Independent LCCE | E20: تم الرد على مدير المشروع بعدم حاجة المشروع الى LCCE مستقل | G20: مكتمل
A21: 9 | B21: 46139 | C21: 3 - Affordability Estimate | D21: TCO | E21: تم طلب عمل TCO تقرير تكلفة الكاملة للاستحواذ من قبل مدير المشروع | G21: مكتمل
A22: 10 | B22: 46140 | C22: 3 - Affordability Estimate | D22: TCO | E22: تم ارسال نموذج TCO | F22: لا يوجد أي تكاليف إضافية وبالتالي مخرجات TCO مساوية لمخرجات LCCE | G22: مكتمل
A23: 11 | B23: 46145 | C23: 3 - Affordability Estimate | D23: Detailed LCCE | E23: بانتظار رد الجهة المستفيدة على نموذج LCCE | F23: تم ارسال نموذج LCCE من مدير المشروع للجهة المستفيدة | G23: على المسار
A24: 12 | B24: 46149 | C24: 3 - Affordability Estimate | D24: Detailed LCCE | E24: بانتظار رد الجهة المستفيدة على نموذج LCCE | F24: تم ارسال نموذج LCCE من مدير المشروع للجهة المستفيدة | G24: على المسار
A25: 13 | B25: 46152 | C25: 3 - Affordability Estimate | D25: Detailed LCCE | E25: بانتظار رد الجهة المستفيدة على نموذج LCCE | F25: تم ارسال نموذج LCCE من مدير المشروع للجهة المستفيدة تم ارسال ايميل اخر من قبل مدير المشروع للجهة المستفيدة للموظف البديل عن الممثل وذلك بسبب وجود إجازة مرضية مطولة للمثل الجهة المستفيدة السابق. | G25: على المسار
A26: 14 | B26: 46154 | C26: 3 - Affordability Estimate | E26: تم عقد اجتماع تدريب المفصل للمرحلة القادمة | F26: تم شرح مخطط الاجرائي رقم 5،6 يوجد خطوتين يكون هناك دور للتكاليف وهي مخطط 6.1.1 + 6.1.2 ، كما ان تم ذكر بوجود ملاحظة بحيث ان اجراء تحديث LCCE قبل خطوة تحديث الامدال بالاظافة الى عدم وجود مسار يوضح إجراءات وخطوات الإدارة العامة للتكاليف | G26: مكتمل
A27: 15 | B27: 46156 | C27: 3 - Affordability Estimate | D27: Independent LCCE | E27: تم موافقة الجهة المستفيدة على LCCE | F27: تم موافقة الجهة المستفيدة على التكلفة وتفاصيل البنود في نموذج LCCE | G27: مكتمل
A28: 16 | B28: 46156 | C28: 4 - Tender Pack Development | E28: تم تحديد نوع الشراء وهي منافسة عامة | F28: موافقة إدارة مدير المشروع على تحديد نوع المنافسة وهي منافسة عامة | G28: مكتمل
A29: 17 | B29: 46156 | C29: 4 - Tender Pack Development | E29: تحديث ملف WBS من قبل مدير المشروع | F29: سيتم حديث ملف WBS من قبل مدير الشمروع وذلك بسبب ان مسار المشروع مدموج بين com & tom معا ، فيتطلب تحديث الجدول الزمني المتوقع للمشروع ليتمشى مع Com قبل ان يتم مشاركة مدير المشروع لإدارته جميع المدخلات لاخذ الموافقة عليها . | G29: على المسار
A30: 18 | B30: 46159 | C30: 4 - Tender Pack Development | E30: لم يتم حظور مدير المشروع. شرح خطوات تعبئة نموذج استرتيجية التوريد (SOURCING STRATEGY) من قبل مدير المشروع . | F30: يوجد نموذج مكون من (19) صفحة لابد من مدير المشروع تعبئته ، ذكروا مدراء المشاريع بالاجتماع بعدم الرضا عن الانموذج وذكر بان بعض البنود ليس من اختصاصهم بالإضافة الى ان النموذج لاينطبق على مشاريع التموين والخدمات ، بالإضافة الى ان النموذج سوف يأثر على وقت سير المشروع والمشاريع المستقبلية. (ذكر ممثل الشركة بانه سوف يتم مناقشة الامر مع الادارة والرد في الاجتماع القادم يوم الخميس). | G30: على المسار
A31: 19 | B31: 46163 | C31: 4 - Tender Pack Development | E31: متابعة شرح خطوات تعبئة نموذج استرتيجية التوريد (SOURCING STRATEGY) من قبل مدير المشروع ، ومناقشة الملاحظات | F31: حتى الان لم يتم الانتهاء من تعبئة النموذج مع وجود بعض الملاحظات من قبل مدير المشروع على النموذج ومناقشتها . | G31: على المسار
A32: 20 | B32: 46184 | C32: 4 - Tender Pack Development | E32: لم يتم حظور مدير المشروع | F32: حتى الان لم يتم الانتهاء من تعبئة النموذج مع علما بان (3) المشاريع لم يتم الانتهاء من هذه الخطوة ماعدا مشروعه وحد تم الانتهاء من نموذج استراتيجية التوريد. | G32: متأخر
A33: 21 | B33: 46187 | C33: 4 - Tender Pack Development | E33: استكمال تعبئة النموذج | F33: حظور مدير المشروع ومناقشة بعض النقاط ، وسوف يقوم ببتعديلات أخيرة وتزود الجهة المستفيدة بالنموذج للمراجعة وابداء الملاحظات او الاعتماد للنتقال للخطوة التالية ، علما بأن تم وضع الاجتماع القادم هو نهاية الفترة المحدده لهذا النموذج ، وتم طلب تزويد ومشاركة فريق السياسات بالملاحظات على النموذج. | G33: متأخر
A34: 22 | B34: 46191 | C34: 4 - Tender Pack Development | E34: الانتهاء من تعبئة النوذج، وانتظار الموافقه من قبل المدير المباشر لمدير المشروع | F34: تم إعطاء الملاظات النهائية على النموذج من قبل مدير المشروع ، بالاظافة الى ان النموذج لم يتم التسليم الى الان وينتظر اطلاع الإدارة عليه واعطائه الموفقه على المدخلات والملاحظات على نموذج استراتيجية التوريد. | G34: متأخر
A35: 23
A36: 24
A37: 25
A38: 26
A39: 27
A40: 28
A41: 29
A42: 30
...

Sheet Sheet1
F2: مكتمل | H2: تأخير
F3: على المسار | H3: توقف
F4: متأخر | H4: جودة المخرجات
F5: خطر | H5: تحسين

Sheet SS-03
A1: =IF(B4="","PP-03",B4) -> بدلة الكشف وبدلة الإزالة لصالح القوات البرية
A3: معلومات المشروع
A4: اسم المشروع | B4: بدلة الكشف وبدلة الإزالة لصالح القوات البرية
A5: المختص | B5: محمد اليوسف | C5: الإدارة | D5: SS
A7: الحالة | E7: بداية مرحلة Needs Identifications | F7: 46014
A8: المرحلة الحالية | B8: =IFERROR(LOOKUP(2,1/(C13:C72<>""),C13:C72),"—") -> 3 - Affordability Estimate | E8: نهاية مرحلة Need Identifications | F8: 46035
A9: تاريخ تحديث | B9: =IFERROR(LOOKUP(2,1/(B13:B72<>""),B13:B72),"—") -> 46192 | E9: بداية مرحلة Affordability Estimate | F9: 46057
A10: التحديث | B10: =IFERROR(INDEX(E13:E72,MATCH(MAX(B13:B72),B13:B72,0)),"—") -> لايوجد | E10: نهاية مرحلة Affordability Estimate | F10: on going
A11: سجل سير المشروع
A12: تسلسل | B12: التاريخ | C12: مرحلة سلسلة القيمة | D12: المخرجات | E12: التحديث | F12: ملاحظات | G12: الحالة
A13: 1 | B13: 46014 | C13: 2 - Needs Identification | D13: High Level LCCE | E13: تم استلام قائمة الافتراضات من مدير المشروع | F13: لايوجد ملاحظات على قائمة الافتراضات | G13: على المسار
A14: 2 | B14: 46014 | C14: 2 - Needs Identification | D14: High Level LCCE | E14: تم استلام سجل المخاطر من مدير المشروع | F14: لايوجد ملاحظات على سجل المخاطر | G14: على المسار
A15: 3 | B15: 46021 | C15: 2 - Needs Identification | D15: High Level LCCE | E15: تم مناقشة مدير المشروع بقائمة الأسعار | F15: تم مصادقة مدير المشروع على الأسعار | G15: على المسار
A16: 4 | B16: 46035 | C16: 2 - Needs Identification | D16: High Level LCCE | E16: تم اصدار النموذج دورة حياة المنتج الأولي | F16: بعد مراجعته مع مدير المشروع | G16: مكتمل
A17: 5 | B17: 46057 | C17: 3 - Affordability Estimate | D17: Detailed LCCE | E17: تم مناقشة الأسعار بشكل موسع مع مدير المشروع بعد الاجتماع مع الجهة الطالبة | F17: تم الاجتماع مع الجهة المستفيدة للاستفادة من خبراتهم. | G17: على المسار
A18: 6 | B18: 46064 | C18: 3 - Affordability Estimate | D18: Detailed LCCE | E18: تم اعتماد نموذج دورة حياة المنتج المفصلة | F18: لم يتم تغيير الأسعار عن نسخة نموذج دورة حياة المنتج الأولية. | G18: مكتمل
A19: 7 | B19: 46118 | C19: 3 - Affordability Estimate | D19: Validation | E19: مراجعة نموذج دورة حياة المنتج | F19: تم مراجعة نموذج دورة حياة المنتج مع الأستاذة منال المالك | G19: مكتمل
A20: 8 | B20: 46140 | C20: 3 - Affordability Estimate | D20: TCO | E20: تم ارسال نموذج التكلفة الكلية للاستحواذ | F20: تم االأخذ بالاعتبار أن نموذج دورة حياة المنتج هو يساوي التكلفة الكلية للاستحواذ | G20: مكتمل
A21: 9 | B21: 46142 | C21: 3 - Affordability Estimate | D21: TCO | E21: لايوجد | F21: كل الإجراءات المطلوبة حتى هذه المرحلة تمت وبانتظار التحديث من فريق ديلويت | G21: على المسار
A22: 10 | B22: 46145 | C22: 3 - Affordability Estimate | D22: TCO | E22: لايوجد | F22: كل الإجراءات المطلوبة حتى هذه المرحلة تمت وبانتظار التحديث من فريق ديلويت | G22: على المسار
A23: 11 | B23: 46149 | C23: 3 - Affordability Estimate | D23: TCO | E23: لايوجد | F23: تم حضور الاجتماع وبإنتظار ارسال الجهة المستفيدة الارتباط المالي الجديد للمشروع او تعديل الكميات حيث أن التكلفة التقديرية كانت اعلى من الارتباط المالي بثلاثه بالمية | G23: على المسار
A24: 12 | B24: 46152 | C24: 3 - Affordability Estimate | D24: TCO | E24: لايوجد | F24: تم حضور ورشة عمل في يوم الثلاثاء والأربعاء 12-13 مايو بخصوص المرحلة القادمة بعد مايتم عمل إجراءات داخلية بين المستفيد النهائي ومدير المشروع | G24: على المسار
... A29: 17 | B29: 46192 | C29: 3 - Affordability Estimate | D29: TCO | E29: لايوجد | F29: لازال مدير المشروع يعمل مع المستفيد النهائي على المتطلبات بالتنسيق مع فريق ديلويت | G29: متأخر
A30: 18
A31: 19
A32: 20
A33: 21
A34: 22
A35: 23
A36: 24
A37: 25
A38: 26
A39: 27
A40: 28
A41: 29
... A72: 60

Sheet SS-04
A1: =IF(B4="","PP-04",B4) -> تأمين ملبوسات عسكرية لكليه الدفاع الجوي من الاتفاقية الاطارية
A3: معلومات المشروع
A4: اسم المشروع | B4: تأمين ملبوسات عسكرية لكليه الدفاع الجوي من الاتفاقية الاطارية
A5: المختص | B5: هيا المهنا | C5: الإدارة | D5: SS
A7: الحالة | E7: بداية مرحلة Needs Identifications
A8: المرحلة الحالية | B8: =IFERROR(LOOKUP(2,1/(C13:C72<>""),C13:C72),"—") -> 8 - Contract Execution | E8: نهاية مرحلة Need Identifications
A9: تاريخ تحديث | B9: =IFERROR(LOOKUP(2,1/(B13:B72<>""),B13:B72),"—") -> 46076 | E9: بداية مرحلة Affordability Estimate
A10: التحديث | B10: =IFERROR(INDEX(E13:E72,MATCH(MAX(B13:B72),B13:B72,0)),"—") -> المشروع اتفاقية اطارية وبمرحلة تنفيذ العقد ولا يوجد متطلب على إدارة التكاليف | E10: نهاية مرحلة Affordability Estimate
A11: سجل سير المشروع
A12: تسلسل | B12: التاريخ | C12: مرحلة سلسلة القيمة | D12: المخرجات | E12: التحديث | F12: ملاحظات | G12: الحالة
A13: 1 | B13: 46076 | C13: 8 - Contract Execution | E13: المشروع اتفاقية اطارية وبمرحلة تنفيذ العقد ولا يوجد متطلب على إدارة التكاليف | F13: تم اشراك إدارة التكاليف بالمشروع من مرحلة تنفيذ العقد ولا يتطلب مخرجات على إدارة التكاليف | G13: مكتمل
A14: 2
A15: 3
A16: 4
A17: 5
A18: 6
A19: 7
A20: 8
A21: 9
A22: 10
A23: 11
A24: 12
A25: 13
... A72: 60

Sheet SS-05
A1: =IF(B4="","SMRO-01",B4) -> معدات تغطية إعلامية شاملة
A3: معلومات المشروع
A4: اسم المشروع | B4: معدات تغطية إعلامية شاملة
A5: المختص | B5: محمد اليوسف | C5: الإدارة | D5: SS
A7: الحالة | E7: بداية مرحلة Needs Identifications
A8: المرحلة الحالية | B8: =IFERROR(LOOKUP(2,1/(C13:C72<>""),C13:C72),"—") -> 2 - Needs Identification | E8: نهاية مرحلة Need Identifications
A9: تاريخ تحديث | B9: =IFERROR(LOOKUP(2,1/(B13:B72<>""),B13:B72),"—") -> 46156 | E9: بداية مرحلة Affordability Estimate
A10: التحديث | B10: =IFERROR(INDEX(E13:E72,MATCH(MAX(B13:B72),B13:B72,0)),"—") -> لم يتم بدء دور إدارة التكاليف حتى الآن بناءا على التنسيق مع إدارة المحافظ | E10: نهاية مرحلة Affordability Estimate
A11: سجل سير المشروع
A12: تسلسل | B12: التاريخ | C12: مرحلة سلسلة القيمة | D12: المخرجات | E12: التحديث | F12: ملاحظات | G12: الحالة
A13: 1 | B13: 46149 | C13: 2 - Needs Identification | E13: تم استلام الـ ARF من قبل الـ PPP&B وكان لديهم ملاحظات على جودة بعض المدخلات | F13: طلب من الجهة المستفيدة مراجعة جودة المدخلات | G13: على المسار
A14: 2 | B14: 46156 | C14: 2 - Needs Identification | E14: لم يتم بدء دور إدارة التكاليف حتى الآن بناءا على التنسيق مع إدارة المحافظ | G14: على المسار
A15: 3
A16: 4
A17: 5
A18: 6
A19: 7
A20: 8
A21: 9
A22: 10
A23: 11
A24: 12
A25: 13
A26: 14
... A72: 60

Sheet SS-06
A1: =IF(B4="","SMRO-02",B4) -> رشاش عيار 40 ام كي 19 مع ملحقاته
A3: معلومات المشروع
A4: اسم المشروع | B4: رشاش عيار 40 ام كي 19 مع ملحقاته
A5: المختص | B5: هيا المهنا | C5: الإدارة | D5: SS
A7: الحالة | E7: بداية مرحلة Needs Identifications
A8: المرحلة الحالية | B8: =IFERROR(LOOKUP(2,1/(C13:C72<>""),C13:C72),"—") -> 2 - Needs Identification | E8: نهاية مرحلة Need Identifications
A9: تاريخ تحديث | B9: =IFERROR(LOOKUP(2,1/(B13:B72<>""),B13:B72),"—") -> 46163 | E9: بداية مرحلة Affordability Estimate
A10: التحديث | B10: =IFERROR(INDEX(E13:E72,MATCH(MAX(B13:B72),B13:B72,0)),"—") -> لا يوجد متطلب على إدارة التكاليف حتى الان | E10: نهاية مرحلة Affordability Estimate
A11: سجل سير المشروع
A12: تسلسل | B12: التاريخ | C12: مرحلة سلسلة القيمة | D12: المخرجات | E12: التحديث | F12: ملاحظات | G12: الحالة
A13: 1 | B13: 46138 | C13: 2 - Needs Identification | E13: اخر اجتماع كان بتاريخ 2026/04/26 يوم الاحد وتم تعبئة نموذج الاستخواذ من قبل مدير المشروع والجهة الطالبة | G13: على المسار
A14: 2 | B14: 46145 | C14: 2 - Needs Identification | E14: تم الغاء الاجتماع | G14: متأخر
A15: 3 | B15: 46145 | C15: 2 - Needs Identification | E15: أفاد ممثل الجهة المستفيدة بأنه سيتم إرسال ARF بتاريخ 07-05-2026 | F15: تم شرح دور الجهة المستفيدة في تعبئة نموذج ال ARF | G15: متأخر
A16: 4 | B16: 46156 | C16: 2 - Needs Identification | E16: تم الغاء الاجتماع | G16: متأخر
A17: 5 | B17: 46159 | C17: 2 - Needs Identification | E17: لا يوجد متطلب على إدارة التكاليف حتى الان | F17: تعبئة نموذج الافتراضات (MDAL) من قبل مدير المشروع للانتقال للخطوات القادمة | G17: على المسار
A18: 6 | B18: 46163 | C18: 2 - Needs Identification | E18: لا يوجد متطلب على إدارة التكاليف حتى الان | F18: تعبئة نموذج الافتراضات (MDAL) من قبل مدير المشروع للانتقال للخطوات القادمة | G18: على المسار
A19: 7
A20: 8
A21: 9
A22: 10
A23: 11
A24: 12
A25: 13
A26: 14
A27: 15
A28: 16
A29: 17
A30: 18
... A72: 60

Sheet SS-07
A1: =IF(B4="","SMRO-03",B4) -> تقديم الخدمات الاستشارية الفنية للحصول على شهادات
A3: معلومات المشروع
A4: اسم المشروع | B4: تقديم الخدمات الاستشارية الفنية للحصول على شهادات
A5: المختص | B5: عبدالله النويصر | C5: الإدارة | D5: SS
A7: الحالة | E7: بداية مرحلة
A8: المرحلة الحالية | B8: =IFERROR(LOOKUP(2,1/(C13:C72<>""),C13:C72),"—") -> 8 - Contract Execution | E8: نهاية مرحلة
A9: تاريخ تحديث | B9: =IFERROR(LOOKUP(2,1/(B13:B72<>""),B13:B72),"—") -> 46076 | E9: بداية مرحلة
A10: التحديث | B10: =IFERROR(INDEX(E13:E72,MATCH(MAX(B13:B72),B13:B72,0)),"—") -> 0 | E10: نهاية مرحلة
A11: سجل سير المشروع
A12: تسلسل | B12: التاريخ | C12: مرحلة سلسلة القيمة | D12: المخرجات | E12: التحديث | F12: ملاحظات | G12: الحالة
A13: 1 | B13: 46076 | C13: 8 - Contract Execution | F13: تم اشراك إدارة التكاليف بالمشروع من مرحلة تنفيذ العقد ولا يتطلب مخرجات على إدارة التكاليف | G13: مكتمل
A14: 2
A15: 3
A16: 4
A17: 5
A18: 6
A19: 7
A20: 8
A21: 9
A22: 10
A23: 11
A24: 12
A25: 13
... A72: 60

Sheet MM
A1: رقم المشروع | B1: اسم المشروع | C1: الموجة
A2: SS-01 | B2: توفير مواد خام وقطع الغيار لمطابع وزارة الدفاع (اتفاقية اطارية)
A3: SS-02 | B3: توريد وتخديم المواد الغذائية لمرافق الأندية والضيافات بالمنطقة الوسطى
A4: SS-03 | B4: بدلة الكشف وبدلة الإزالة لصالح القوات البرية
A5: SS-04 | B5: تأمين ملبوسات عسكرية لكليه الدفاع الجوي من الاتفاقية الاطارية
A6: SS-05 | B6: معدات تغطية إعلامية شاملة
A7: SS-06 | B7: رشاش عيار 40 ام كي 19 مع ملحقاته
A8: SS-07 | B8: تقديم الخدمات الاستشارية الفنية للحصول على شهادات

Sheet _REF
A1: Needs | B1: Affordability
A2: CES | B2: Detailed LCCE
A3: High Level LCCE | B3: Validation
B4: Independent LCCE
B5: TCO
